Workbook

Sheet Titelblad
C4: [ Plaats hier je logo ]
B13: GELDPLANNER
B14: Grip op je geld — cashflow, pensioen en vermogensopbouw in één overzicht
B18: Welkom bij Geldplanner. Deze werkmap geeft je in een paar minuten overzicht over je maandelijkse cashflow, je pensioengat en de groei van je vermogen — met heldere, aanpasbare formules in plaats van een kant-en-klaar zwart doosje. Vul de gele cellen op de tabbladen in; het Dashboard werkt automatisch bij.
B23: WAT ZIT ERIN?
C24: ◆ Dashboard — je financiële situatie in één oogopslag
C25: ◆ Cashflow Overzicht — inkomsten, lasten en je maandelijkse overschot
C26: ◆ Pensioengat Calculator — wat je AOW en pensioen missen, en wat je daarvoor opzij zet
C27: ◆ Vermogensgroei — de projectie van je spaargeld en beleggingen
B29: → Ga naar het tabblad 'Dashboard' om te beginnen
B31: Geldplanner · Versie 1.0 · Deze tool is uitsluitend bedoeld voor informatieve doeleinden en biedt geen financieel advies. Zie het tabblad 'Instructies' voor de volledige toelichting.

Sheet Dashboard
B2: Dashboard
B3: Jouw financiële situatie in één oogopslag — werkt automatisch bij zodra je de andere tabbladen invult
B6: € MAANDELIJKS OVERSCHOT / TEKORT | E6: % SPAARQUOTE
B7: ='Cashflow Overzicht'!C40 | E7: =IF('Cashflow Overzicht'!C41="","–",'Cashflow Overzicht'!C41)
B10: =IF('Cashflow Overzicht'!C40>=0,"✓ Je houdt geld over","⚠ Je geeft meer uit dan je binnenkrijgt") | E10: =IF('Cashflow Overzicht'!C41="","Nog geen data",IF('Cashflow Overzicht'!C41>=0.1,"✓ Gezonde spaarquote",IF('Cashflow Overzicht'!C41>=0,"⚠ Kan beter","✕ Tekort")))
B13: ◆ PENSIOENGAT | E13: =CONCATENATE("↗ VERWACHT VERMOGEN OVER ",'Vermogensgroei'!C14," JAAR")
B14: ='Pensioengat Calculator'!C33 | E14: ='Vermogensgroei'!C23
B17: =IF('Pensioengat Calculator'!C33<=0,"✓ Op koers","⚠ Actie nodig") | E17: =CONCATENATE("Koopkracht van nu: € ",TEXT('Vermogensgroei'!C26,"#,##0"))
B21: ◆ AAN DE SLAG
B22: 1 Vul je cijfers in op 'Cashflow Overzicht', 'Pensioengat Calculator' en 'Vermogensgroei'.
B23: 2 Kom terug naar dit Dashboard — de kaarten hierboven werken automatisch bij.
B24: 3 Je maandelijkse overschot loopt automatisch door als voorstel voor je inleg bij pensioen en vermogen; dit kun je op elk tabblad overschrijven.
B25: 4 Twijfel je over de kleurcodering of de formules? Kijk op het tabblad 'Instructies'.
B27: Deze tool is uitsluitend bedoeld voor informatieve doeleinden en biedt geen financieel advies.

Sheet Instructies
B2: Geldplanner
B3: Persoonlijk financieel overzicht voor Nederlandse huishoudens
B5: Welkom
B6: Deze werkmap helpt je in kaart te brengen wat er maandelijks binnenkomt en weggaat, hoe groot je
B7: pensioengat is en hoe je vermogen groeit. Het Dashboard geeft een direct overzicht van je situatie.
B8: Vul alleen de gele cellen in. De grijze, blauwe en goudkleurige cellen bevatten formules en zijn vergrendeld.
B10: ◆ DE TABBLADEN
B11: Tabblad | C11: Wat doe je hier?
B12: 1. Titelblad | C12: Voorblad met een plek voor je eigen logo, de productnaam en een korte introductie.
B13: 2. Dashboard | C13: Vier KPI-kaarten die automatisch bijwerken vanuit de andere tabbladen: je maandelijkse overschot, je spaarquote, de status van je pensioengat en je verwachte vermogen.
B14: 3. Instructies | C14: Deze pagina: uitleg, kleurcodering en de disclaimer.
B15: 4. Cashflow Overzicht | C15: Vul je maandelijkse inkomsten, vaste lasten en variabele kosten in. Je ziet direct je totale inkomsten, totale uitgaven, het maandelijkse overschot of tekort en je spaarquote.
B16: 5. Pensioengat Calculator | C16: Vul je leeftijd, gewenste pensioenleeftijd, gewenst pensioeninkomen, opgebouwd pensioenvermogen en verwachte AOW in. Je maandelijkse overschot uit 'Cashflow Overzicht' loopt automatisch door als voorstel voor je pensioeninleg; je kunt dit overschrijven.
B17: 6. Vermogensgroei | C17: Vul je startkapitaal, verwacht rendement en looptijd in. Ook hier loopt je overschot uit 'Cashflow Overzicht' automatisch door als voorstel voor je maandelijkse inleg. Je ziet de geprojecteerde waarde per jaar plus een grafiek van de groei.
B19: ◆ KLEURCODERING
B20: Invoercel (geel) | C20: Hier vul je zelf iets in. Alleen deze cellen zijn bewerkbaar.
B21: Berekende cel (grijs) | C21: Bevat een formule. Vergrendeld zodat je niet per ongeluk een berekening overschrijft.
B22: Sectieresultaat (blauw) | C22: Het eindresultaat van een sectie. Ook vergrendeld.
B23: Hoofduitkomst (goud, groot) | C23: De belangrijkste cijfer van het hele tabblad, bijvoorbeeld je pensioengat.
B25: Op het Dashboard betekent een groene badge dat je situatie gezond is, oranje dat er een aandachtspunt is en rood dat directe actie nodig is.
B27: ◆ ZO GEBRUIK JE DE WERKMAP
B28: 1. Begin bij 'Cashflow Overzicht' en vul je maandbudget in. Alles wat niet van toepassing is laat je op 0 staan.
B29: 2. Bekijk het 'Dashboard' voor een overzicht van je situatie.
B30: 3. Ga naar 'Pensioengat Calculator' en 'Vermogensgroei'. Je maandelijkse overschot uit stap 1 loopt daar automatisch door als voorstel voor je inleg — kies 'Nee' bij de koppeling om je eigen bedrag te gebruiken.
B31: 4. De bladen zijn beveiligd zonder wachtwoord. Wil je formules aanpassen? Controleren > Blad-beveiliging opheffen.
B32: 5. Bedragen staan in euro's. Op een Nederlandse Excel-installatie verschijnen ze als € 1.234,56.
B34: ◆ BELANGRIJK — DISCLAIMER
B35: Deze tool is uitsluitend bedoeld voor informatieve doeleinden en biedt geen financieel advies. Rendementen uit het verleden bieden geen garantie voor de toekomst; beleggen brengt risico's met zich mee en je kunt je inleg verliezen. De berekeningen zijn schattingen op basis van de aannames die je zelf invult. Raadpleeg voor persoonlijk advies een financieel adviseur.

Sheet Cashflow Overzicht
B2: Cashflow Overzicht
B3: Wat komt er maandelijks binnen en wat gaat eruit?
B5: ◆ INKOMSTEN PER MAAND
B6: Nettosalaris persoon 1 | C6: 3600 | D6: Bedrag dat op je rekening staat
B7: Nettosalaris persoon 2 | C7: 0 | D7: Laat op 0 staan als je alleenstaand bent
B8: Freelance-inkomsten (netto) | C8: 0 | D8: Netto bedrag, na belasting
B9: Toeslagen (huur-, zorg-, kinderopvang) | C9: 0
B10: Huurinkomsten / alimentatie | C10: 0
B11: Overige inkomsten | C11: 0
B12: Totale inkomsten | C12: =SUM(C6:C11)
B14: ◆ VASTE LASTEN PER MAAND
B15: Huur of hypotheek | C15: 1250
B16: Energie, water en warmte | C16: 180
B17: Zorgverzekering | C17: 290 | D17: Beide partners samen
B18: Overige verzekeringen | C18: 65 | D18: Inboedel, aansprakelijkheid, opstal, ORV
B19: Gemeentelijke belastingen en waterschap | C19: 60 | D19: Jaarbedrag gedeeld door 12
B20: Internet, tv en telefoon | C20: 70
B21: Abonnementen en lidmaatschappen | C21: 45 | D21: Streaming, sportschool, kranten
B22: Aflossing leningen en studieschuld | C22: 0
B23: Kinderopvang / school | C23: 0
B24: Overige vaste lasten | C24: 0
B25: Totaal vaste lasten | C25: =SUM(C15:C24)
B27: ◆ VARIABELE KOSTEN PER MAAND
B28: Boodschappen | C28: 550
B29: Vervoer (brandstof, OV, onderhoud) | C29: 200
B30: Vrije tijd, uitgaan en horeca | C30: 200
B31: Kleding en persoonlijke verzorging | C31: 100
B32: Zorgkosten (eigen risico, tandarts) | C32: 40
B33: Vakantie (gereserveerd per maand) | C33: 150
B34: Cadeaus, goede doelen en overig | C34: 75
B35: Totaal variabele kosten | C35: =SUM(C28:C34)
B37: ◆ RESULTAAT
B38: Totale inkomsten | C38: =C12
B39: Totale uitgaven | C39: =C25+C35
B40: Maandelijks overschot / tekort | C40: =C38-C39 | D40: Positief = je houdt over. Negatief = je komt tekort.
B41: Spaarquote | C41: =IF(C38=0,"",C40/C38) | D41: Deel van je inkomen dat je overhoudt
B42: Overschot / tekort per jaar | C42: =C40*12
B43: Vaste lasten als deel van inkomen | C43: =IF(C38=0,"",C25/C38) | D43: Vuistregel: houd dit onder 50%
B44: Buffer: hoeveel maanden uitgaven heb je? | C44: =IF(C25+C35=0,"",C46/(C25+C35)) | D44: Vuistregel: drie tot zes maanden
B46: Huidig spaargeld (buffer) | C46: 5000 | D46: Wordt gebruikt voor de bufferberekening hierboven
...

Sheet Pensioengat Calculator
B2: Pensioengat Calculator
B3: Hoeveel moet je maandelijks opzijzetten voor het pensioen dat je wilt?
B5: ◆ JOUW SITUATIE
B6: Huidige leeftijd | C6: 38
B7: Gewenste pensioenleeftijd | C7: 67 | D7: De AOW-leeftijd is nu 67 jaar en beweegt mee met de levensverwachting
B8: Gewenst pensioeninkomen per maand | C8: 3500 | D8: In euro's van vandaag, netto besteedbaar
B9: Verwachte AOW per maand | C9: 1500 | D9: Ca. € 1.050 alleenstaand, ca. € 750 p.p. samenwonend (netto, 2025)
B10: Verwacht werkgeverspensioen per maand | C10: 700 | D10: Zie mijnpensioenoverzicht.nl
B11: Huidig opgebouwd pensioenvermogen | C11: 30000 | D11: Lijfrente, banksparen, beleggingen bestemd voor pensioen
B13: ◆ KOPPELING MET CASHFLOW OVERZICHT
B14: Voorstel: maandelijks overschot uit Cashflow Overzicht | C14: ='Cashflow Overzicht'!C40 | D14: Wordt automatisch bijgewerkt zodra je dat tabblad invult
B15: Gebruik dit voorstel als je huidige pensioeninleg? | C15: Ja | D15: Kies 'Nee' om je eigen bedrag hieronder te gebruiken
B16: Eigen invoer (alleen gebruikt bij 'Nee') | C16: 150 | D16: Vul hier je eigen maandelijkse pensioeninleg in
B17: Wat leg je nu al maandelijks in? | C17: =IF(C15="Ja",C14,C16) | D17: Gebruikt in de berekening hieronder
B19: ◆ AANNAMES
B20: Verwacht rendement vóór pensioen (per jaar) | C20: 0.05 | D20: Historisch wereldwijd aandelenrendement ligt rond 6-7% nominaal
B21: Verwacht rendement tijdens pensioen (per jaar) | C21: 0.03 | D21: Meestal lager: je bouwt risico af
B22: Verwachte inflatie (per jaar) | C22: 0.02 | D22: Doelstelling van de ECB is 2%
B23: Aantal jaren dat je pensioen moet duren | C23: 25 | D23: Levensverwachting bij 67 is ruim 18 jaar; 25 is voorzichtig
B25: ◆ HET PENSIOENGAT
B26: Jaren tot je pensioen | C26: =MAX(0,C7-C6)
B27: Maandelijks tekort in euro's van vandaag | C27: =MAX(0,C8-C9-C10) | D27: Gewenst inkomen minus AOW en werkgeverspensioen
B28: Maandelijks tekort bij pensionering | C28: =C27*(1+C22)^C26 | D28: Hetzelfde tekort, gecorrigeerd voor inflatie
B29: Reëel rendement tijdens pensioen | C29: =(1+C21)/(1+C22)-1 | D29: Rendement minus inflatie; houdt je uitkering koopkrachtvast
B30: Benodigd pensioenkapitaal bij pensionering | C30: =IF(ABS(C29)<0.0001,C28*12*C23,C28*12*(1-(1+C29)^(-C23))/C29) | D30: Contante waarde van het tekort over de hele pensioenperiode
B31: Waarde van je huidige vermogen bij pensionering | C31: =C11*(1+C20)^C26 | D31: Je opgebouwde vermogen groeit door tot je pensioendatum
B32: Waarde van je huidige maandinleg bij pensionering | C32: =IF(OR(C26=0,C20=0),C17*12*C26,C17*(((1+(1+C20)^(1/12)-1)^(C26*12)-1)/((1+C20)^(1/12)-1))) | D32: Wat je huidige inleg oplevert als je die volhoudt
B33: PENSIOENGAT (tekort aan kapitaal) | C33: =MAX(0,C30-C31-C32) | D33: Nul betekent: je ligt op koers
B35: ◆ WAT MOET JE DOEN?
B36: Maandelijks rendement (samengesteld) | C36: =(1+C20)^(1/12)-1 | D36: Jaarrendement omgerekend naar maandbasis
B37: Extra maandelijks sparen of beleggen | C37: =IF(C26<=0,"",IF(C33<=0,0,IF(C36=0,C33/(C26*12),C33*C36/((1+C36)^(C26*12)-1)))) | D37: Bovenop wat je nu al inlegt
B38: Totale maandelijkse inleg vanaf nu | C38: =IF(C37="","",C17+C37) | D38: Je huidige inleg plus het extra bedrag
B39: Totaal dat je zelf inlegt tot pensioendatum | C39: =IF(C38="","",C38*12*C26) | D39: Zonder rendement, alleen je eigen geld
B40: Dekkingsgraad zonder extra inleg | C40: =IF(C30<=0,"",(C31+C32)/C30) | D40: 100% = je huidige plan is toereikend
B42: Hoe deze berekening werkt
B43: • Je maandelijkse inleg is gekoppeld aan je overschot in 'Cashflow Overzicht'; kies 'Nee' bij de koppeling hierboven om je eigen bedrag te gebruiken.
B44: • Je gewenste inkomen wordt met de inflatie opgehoogd naar je pensioendatum.
B45: • Het benodigde kapitaal is de contante waarde van je maandelijkse tekort over de hele pensioenperiode,
B46: verdisconteerd tegen het reële rendement, zodat je uitkering koopkrachtvast blijft.
B47: • De benodigde inleg volgt uit de standaardformule voor samengestelde rente met periodieke stortingen.
...

Sheet Vermogensgroei
B2: Vermogensgroei
B3: Projectie van je vermogen met samengestelde rente
B5: ◆ KOPPELING MET CASHFLOW OVERZICHT
B6: Voorstel: maandelijks overschot uit Cashflow Overzicht | C6: ='Cashflow Overzicht'!C40 | D6: Wordt automatisch bijgewerkt zodra je dat tabblad invult
B7: Gebruik dit voorstel als maandelijkse inleg? | C7: Ja | D7: Kies 'Nee' om je eigen bedrag hieronder te gebruiken
B8: Eigen invoer (alleen gebruikt bij 'Nee') | C8: 500 | D8: Vul hier je eigen maandelijkse inleg in
B10: ◆ JOUW INVOER
B11: Huidig spaargeld en beleggingen | C11: 25000 | D11: Je startkapitaal
B12: Maandelijkse inleg (gebruikt in de projectie) | C12: =IF(C7="Ja",C6,C8) | D12: Volgt automatisch uit de koppeling hierboven
B13: Verwacht rendement per jaar | C13: 0.06 | D13: Spaarrekening ca. 1,5-2%, wereldwijd aandelenfonds historisch ca. 7%
B14: Aantal jaren | C14: 25 | D14: Maximaal 40 jaar
B15: Verwachte inflatie per jaar | C15: 0.02 | D15: Voor de koopkracht-kolom in de tabel
B16: Beleggingskosten per jaar | C16: 0.0035 | D16: Fondskosten plus servicekosten van je broker
B18: ◆ AFGELEIDE WAARDEN
B19: Netto rendement na kosten | C19: =C13-C16 | D19: Wordt in de projectie gebruikt
B20: Maandelijks rendement (samengesteld) | C20: =(1+C19)^(1/12)-1
B22: ◆ RESULTAAT NA DE GEKOZEN LOOPTIJD
B23: Geprojecteerde eindwaarde | C23: =INDEX(J30:J70,C14+1)
B24: Totaal zelf ingelegd | C24: =INDEX(K30:K70,C14+1)
B25: Waarvan rendement | C25: =C23-C24 | D25: Het deel dat je geld voor je heeft verdiend
B26: Eindwaarde in euro's van nu | C26: =INDEX(L30:L70,C14+1) | D26: Gecorrigeerd voor inflatie: dit is je koopkracht
F29: Jaar | G29: Beginwaarde | H29: Inleg dit jaar | I29: Rendement | J29: Eindwaarde | K29: Totaal ingelegd | L29: Waarde in euro's van nu
F30: =IF(C$14>=0,0,NA()) | G30: =IF(C$14>=0,C$11,NA()) | H30: =IF(C$14>=0,0,NA()) | I30: =IF(C$14>=0,0,NA()) | J30: =IF(C$14>=0,C$11,NA()) | K30: =IF(C$14>=0,C$11,NA()) | L30: =IF(C$14>=0,J30/(1+C$15)^0,NA())
F31: =IF(C$14>=1,1,NA()) | G31: =IF(C$14>=1,J30,NA()) | H31: =IF(C$14>=1,C$12*12,NA()) | I31: =IF(C$14>=1,J31-G31-H31,NA()) | J31: =IF(C$14>=1,G31*(1+C$19)+IF(C$20=0,C$12*12,C$12*((1+C$20)^12-1)/C$20),NA()) | K31: =IF(C$14>=1,K30+H31,NA()) | L31: =IF(C$14>=1,J31/(1+C$15)^1,NA())
F32: =IF(C$14>=2,2,NA()) | G32: =IF(C$14>=2,J31,NA()) | H32: =IF(C$14>=2,C$12*12,NA()) | I32: =IF(C$14>=2,J32-G32-H32,NA()) | J32: =IF(C$14>=2,G32*(1+C$19)+IF(C$20=0,C$12*12,C$12*((1+C$20)^12-1)/C$20),NA()) | K32: =IF(C$14>=2,K31+H32,NA()) | L32: =IF(C$14>=2,J32/(1+C$15)^2,NA())
F33: =IF(C$14>=3,3,NA()) | G33: =IF(C$14>=3,J32,NA()) | H33: =IF(C$14>=3,C$12*12,NA()) | I33: =IF(C$14>=3,J33-G33-H33,NA()) | J33: =IF(C$14>=3,G33*(1+C$19)+IF(C$20=0,C$12*12,C$12*((1+C$20)^12-1)/C$20),NA()) | K33: =IF(C$14>=3,K32+H33,NA()) | L33: =IF(C$14>=3,J33/(1+C$15)^3,NA())
F34: =IF(C$14>=4,4,NA()) | G34: =IF(C$14>=4,J33,NA()) | H34: =IF(C$14>=4,C$12*12,NA()) | I34: =IF(C$14>=4,J34-G34-H34,NA()) | J34: =IF(C$14>=4,G34*(1+C$19)+IF(C$20=0,C$12*12,C$12*((1+C$20)^12-1)/C$20),NA()) | K34: =IF(C$14>=4,K33+H34,NA()) | L34: =IF(C$14>=4,J34/(1+C$15)^4,NA())
F35: =IF(C$14>=5,5,NA()) | G35: =IF(C$14>=5,J34,NA()) | H35: =IF(C$14>=5,C$12*12,NA()) | I35: =IF(C$14>=5,J35-G35-H35,NA()) | J35: =IF(C$14>=5,G35*(1+C$19)+IF(C$20=0,C$12*12,C$12*((1+C$20)^12-1)/C$20),NA()) | K35: =IF(C$14>=5,K34+H35,NA()) | L35: =IF(C$14>=5,J35/(1+C$15)^5,NA())
F36: =IF(C$14>=6,6,NA()) | G36: =IF(C$14>=6,J35,NA()) | H36: =IF(C$14>=6,C$12*12,NA()) | I36: =IF(C$14>=6,J36-G36-H36,NA()) | J36: =IF(C$14>=6,G36*(1+C$19)+IF(C$20=0,C$12*12,C$12*((1+C$20)^12-1)/C$20),NA()) | K36: =IF(C$14>=6,K35+H36,NA()) | L36: =IF(C$14>=6,J36/(1+C$15)^6,NA())
F37: =IF(C$14>=7,7,NA()) | G37: =IF(C$14>=7,J36,NA()) | H37: =IF(C$14>=7,C$12*12,NA()) | I37: =IF(C$14>=7,J37-G37-H37,NA()) | J37: =IF(C$14>=7,G37*(1+C$19)+IF(C$20=0,C$12*12,C$12*((1+C$20)^12-1)/C$20),NA()) | K37: =IF(C$14>=7,K36+H37,NA()) | L37: =IF(C$14>=7,J37/(1+C$15)^7,NA())
F38: =IF(C$14>=8,8,NA()) | G38: =IF(C$14>=8,J37,NA()) | H38: =IF(C$14>=8,C$12*12,NA()) | I38: =IF(C$14>=8,J38-G38-H38,NA()) | J38: =IF(C$14>=8,G38*(1+C$19)+IF(C$20=0,C$12*12,C$12*((1+C$20)^12-1)/C$20),NA()) | K38: =IF(C$14>=8,K37+H38,NA()) | L38: =IF(C$14>=8,J38/(1+C$15)^8,NA())
F39: =IF(C$14>=9,9,NA()) | G39: =IF(C$14>=9,J38,NA()) | H39: =IF(C$14>=9,C$12*12,NA()) | I39: =IF(C$14>=9,J39-G39-H39,NA()) | J39: =IF(C$14>=9,G39*(1+C$19)+IF(C$20=0,C$12*12,C$12*((1+C$20)^12-1)/C$20),NA()) | K39: =IF(C$14>=9,K38+H39,NA()) | L39: =IF(C$14>=9,J39/(1+C$15)^9,NA())
F40: =IF(C$14>=10,10,NA()) | G40: =IF(C$14>=10,J39,NA()) | H40: =IF(C$14>=10,C$12*12,NA()) | I40: =IF(C$14>=10,J40-G40-H40,NA()) | J40: =IF(C$14>=10,G40*(1+C$19)+IF(C$20=0,C$12*12,C$12*((1+C$20)^12-1)/C$20),NA()) | K40: =IF(C$14>=10,K39+H40,NA()) | L40: =IF(C$14>=10,J40/(1+C$15)^10,NA())
F41: =IF(C$14>=11,11,NA()) | G41: =IF(C$14>=11,J40,NA()) | H41: =IF(C$14>=11,C$12*12,NA()) | I41: =IF(C$14>=11,J41-G41-H41,NA()) | J41: =IF(C$14>=11,G41*(1+C$19)+IF(C$20=0,C$12*12,C$12*((1+C$20)^12-1)/C$20),NA()) | K41: =IF(C$14>=11,K40+H41,NA()) | L41: =IF(C$14>=11,J41/(1+C$15)^11,NA())
F42: =IF(C$14>=12,12,NA()) | G42: =IF(C$14>=12,J41,NA()) | H42: =IF(C$14>=12,C$12*12,NA()) | I42: =IF(C$14>=12,J42-G42-H42,NA()) | J42: =IF(C$14>=12,G42*(1+C$19)+IF(C$20=0,C$12*12,C$12*((1+C$20)^12-1)/C$20),NA()) | K42: =IF(C$14>=12,K41+H42,NA()) | L42: =IF(C$14>=12,J42/(1+C$15)^12,NA())
F43: =IF(C$14>=13,13,NA()) | G43: =IF(C$14>=13,J42,NA()) | H43: =IF(C$14>=13,C$12*12,NA()) | I43: =IF(C$14>=13,J43-G43-H43,NA()) | J43: =IF(C$14>=13,G43*(1+C$19)+IF(C$20=0,C$12*12,C$12*((1+C$20)^12-1)/C$20),NA()) | K43: =IF(C$14>=13,K42+H43,NA()) | L43: =IF(C$14>=13,J43/(1+C$15)^13,NA())
F44: =IF(C$14>=14,14,NA()) | G44: =IF(C$14>=14,J43,NA()) | H44: =IF(C$14>=14,C$12*12,NA()) | I44: =IF(C$14>=14,J44-G44-H44,NA()) | J44: =IF(C$14>=14,G44*(1+C$19)+IF(C$20=0,C$12*12,C$12*((1+C$20)^12-1)/C$20),NA()) | K44: =IF(C$14>=14,K43+H44,NA()) | L44: =IF(C$14>=14,J44/(1+C$15)^14,NA())
F45: =IF(C$14>=15,15,NA()) | G45: =IF(C$14>=15,J44,NA()) | H45: =IF(C$14>=15,C$12*12,NA()) | I45: =IF(C$14>=15,J45-G45-H45,NA()) | J45: =IF(C$14>=15,G45*(1+C$19)+IF(C$20=0,C$12*12,C$12*((1+C$20)^12-1)/C$20),NA()) | K45: =IF(C$14>=15,K44+H45,NA()) | L45: =IF(C$14>=15,J45/(1+C$15)^15,NA())
F46: =IF(C$14>=16,16,NA()) | G46: =IF(C$14>=16,J45,NA()) | H46: =IF(C$14>=16,C$12*12,NA()) | I46: =IF(C$14>=16,J46-G46-H46,NA()) | J46: =IF(C$14>=16,G46*(1+C$19)+IF(C$20=0,C$12*12,C$12*((1+C$20)^12-1)/C$20),NA()) | K46: =IF(C$14>=16,K45+H46,NA()) | L46: =IF(C$14>=16,J46/(1+C$15)^16,NA())
F47: =IF(C$14>=17,17,NA()) | G47: =IF(C$14>=17,J46,NA()) | H47: =IF(C$14>=17,C$12*12,NA()) | I47: =IF(C$14>=17,J47-G47-H47,NA()) | J47: =IF(C$14>=17,G47*(1+C$19)+IF(C$20=0,C$12*12,C$12*((1+C$20)^12-1)/C$20),NA()) | K47: =IF(C$14>=17,K46+H47,NA()) | L47: =IF(C$14>=17,J47/(1+C$15)^17,NA())
...
